Workbook

Sheet Sheet1
A1: int-id | B1: int-nextid | C1: string-name | D1: int-constellationid | E1: int-fatestarid | F1: int-starconsume | G1: float-HP | H1: float-attack | I1: float-defense | J1: float-superpower | K1: float-resist | L1: float-crit | M1: float-decrit | N1: float-curse | O1: float-decurse | P1: float-press | Q1: float-depress | R1: float-restoreHP | S1: float-MP | T1: float-restoreMP | U1: intArr:bonus1:|:- | V1: intArr:bonus2:|:- | W1: string-bubble | X1: int-bubbletype | Y1: string-icon | Z1: float-iconsize | AA1: string-sceneid | AB1: float-coordinatex | AC1: float-coordinatey | AD1: string-coname | AE1: stringArr:starpic:| | AF1: string-starp | AG1: intArr:spellawake:|:- | AH1: intArr:spell:| | AI1: int-limitmain | AJ1: intArr:limitguide:|
A2: id | B2: 下一节点id | C2: 节点名称 | D2: 星座id | E2: 命星id | F2: 达到星数 | G2: HP | H2: 攻击力 | I2: 防御力 | J2: 霸气 | K2: 抗性 | L2: 暴击力 | M2: 抗暴力 | N2: 诅咒力 | O2: 抗咒力 | P2: 压制力 | Q2: 抗压力 | R2: HP恢复能力 | S2: MP | T2: MP恢复能力 | U2: 资源奖励 | V2: 物品奖励 | W2: 气泡文字描述 | X2: 气泡显示类型 | Y2: 图标 | Z2: 图标大小系数 | AA2: 背景图 | AB2: x坐标 | AC2: y坐标 | AD2: 星座名称 | AE2: 星座名称图标 | AF2: 星座图标 | AG2: 星宫限制觉醒 | AH2: 星宫限制技能 | AI2: 主线星宫点亮限制条件 | AJ2: 教程副本限制条件
D3: 备注 1-白羊座 2-金牛座 3-双子 | F3: 所有英雄的英雄闯关 总星数之和 | U3: 1-铜币（游戏币） 2-金币（充值获得） 3-竞技场币 4-精力 5-体力 6-远征币 7-帮贡 8-魔王经验 9-经验池 10-魔王技能点 | X3: 1-常驻显示 2-点击弹出 | Y3: 不同星座图标不同 | Z3: 图标的缩放系数 | AA3: 一个星座一个背景 配置在每个星座的第一颗命星的数据中 | AG3: 角色ID-技能觉醒ID| | AI3: 主线副本ID | AJ3: 教程副本
A4: 140001 | B4: 140002 | C4: 白羊座1星 | D4: 1 | E4: 1 | F4: 3 | G4: 0 | H4: 0 | I4: 0 | J4: 0 | K4: 0 | L4: 0 | M4: 0 | N4: 0 | O4: 0 | P4: 0 | Q4: 0 | R4: 0 | S4: 0 | T4: 0 | V4: 400034-1 | W4: 获得英雄：兰斯洛特 | X4: 2 | Y4: zi | Z4: 0.7 | AA4: bg | AB4: -275 | AC4: 65 | AD4: 白羊座 | AE4: baiyangicon|baiyangname | AF4: Icon/skill/S80702121
A5: 140002 | B5: 140003 | C5: 白羊座2星 | D5: 1 | E5: 2 | F5: 12 | G5: 0 | H5: 0 | I5: 0 | J5: 0 | K5: 0 | L5: 0 | M5: 0 | N5: 0 | O5: 0 | P5: 0 | Q5: 0 | R5: 0 | S5: 0 | T5: 0 | W5: 角色升级 | X5: 2 | Y5: lv | Z5: 0.7 | AA5: bg | AB5: -114 | AC5: 7.4 | AD5: 白羊座 | AE5: baiyangicon|baiyangname | AF5: Main/btnTask2
A6: 140003 | B6: 140004 | C6: 白羊座3星 | D6: 1 | E6: 3 | F6: 15 | G6: 0 | H6: 0 | I6: 0 | J6: 0 | K6: 0 | L6: 0 | M6: 0 | N6: 0 | O6: 0 | P6: 0 | Q6: 0 | R6: 0 | S6: 0 | T6: 0 | W6: 铃兰花海5开启 | X6: 2 | Y6: zi | Z6: 0.7 | AA6: bg | AB6: 47 | AC6: -50.2 | AD6: 白羊座 | AE6: baiyangicon|baiyangname | AF6: Main/btnTask1
A7: 140004 | B7: 140005 | C7: 白羊座4星 | D7: 1 | E7: 4 | F7: 18 | G7: 0 | H7: 0 | I7: 0 | J7: 0 | K7: 0 | L7: 0 | M7: 0 | N7: 0 | O7: 0 | P7: 0 | Q7: 0 | R7: 0 | S7: 0 | T7: 0 | W7: 开启芙蕾雅闯关 | X7: 2 | Y7: lan | Z7: 0.7 | AA7: bg | AB7: -20 | AC7: 100 | AD7: 白羊座 | AE7: baiyangicon|baiyangname | AF7: Icon/hero/hero04 | AH7: 804021
A8: 140005 | B8: 140006 | C8: 白羊座5星 | D8: 1 | E8: 5 | F8: 21 | G8: 0 | H8: 0 | I8: 0 | J8: 0 | K8: 0 | L8: 0 | M8: 0 | N8: 0 | O8: 0 | P8: 0 | Q8: 0 | R8: 0 | S8: 0 | T8: 0 | W8: 开启英雄闯关第二章 | X8: 2 | Y8: zi | Z8: 0.7 | AA8: bg | AB8: -20 | AC8: 155 | AD8: 白羊座 | AE8: jinniuicon|jinniuname | AF8: Icon/function/ft005
A9: 140006 | B9: 140007 | C9: 白羊座6星 | D9: 1 | E9: 6 | F9: 24 | G9: 0 | H9: 0 | I9: 0 | J9: 0 | K9: 0 | L9: 0 | M9: 0 | N9: 0 | O9: 0 | P9: 0 | Q9: 0 | R9: 0 | S9: 0 | T9: 0 | W9: 高星闯关开启 | X9: 2 | Y9: cheng | Z9: 0.7 | AA9: bg | AB9: 10 | AC9: 204 | AD9: 白羊座 | AE9: jinniuicon|jinniuname | AF9: GameLevel/hard
A10: 140007 | B10: 140008 | C10: 白羊座7星 | D10: 1 | E10: 7 | F10: 27 | G10: 0 | H10: 0 | I10: 0 | J10: 0 | K10: 0 | L10: 0 | M10: 0 | N10: 0 | O10: 0 | P10: 0 | Q10: 0 | R10: 0 | S10: 0 | T10: 0 | W10: 戒指开启 | X10: 2 | Y10: lv | Z10: 0.7 | AA10: bg | AB10: 57 | AC10: 213 | AD10: 白羊座 | AE10: jinniuicon|jinniuname | AF10: Icon/item/I500083
A11: 140008 | B11: 140009 | C11: 白羊座8星 | D11: 1 | E11: 8 | F11: 33 | G11: 0 | H11: 0 | I11: 0 | J11: 0 | K11: 0 | L11: 0 | M11: 0 | N11: 0 | O11: 0 | P11: 0 | Q11: 0 | R11: 0 | S11: 0 | T11: 0 | V11: 500001-1|500002-1|500003-1 | W11: 英雄升星开启 | X11: 2 | Y11: lan | Z11: 0.7 | AA11: bg | AB11: 143 | AC11: 182 | AD11: 白羊座 | AE11: jinniuicon|jinniuname | AF11: Main/btnTask1
A12: 140009 | B12: 140010 | C12: 白羊座9星 | D12: 1 | E12: 9 | F12: 45 | G12: 0 | H12: 0 | I12: 0 | J12: 0 | K12: 0 | L12: 0 | M12: 0 | N12: 0 | O12: 0 | P12: 0 | Q12: 0 | R12: 0 | S12: 0 | T12: 0 | W12: 开启援助 | X12: 2 | Y12: lv | Z12: 0.7 | AA12: bg | AB12: 183 | AC12: -79 | AD12: 白羊座 | AE12: jinniuicon|jinniuname | AF12: Icon/skill/S805021 | AH12: 805021
A13: 140010 | B13: 140011 | C13: 金牛座1星 | D13: 2 | E13: 1 | F13: 51 | G13: 0 | H13: 0 | I13: 0 | J13: 0 | K13: 0 | L13: 0 | M13: 0 | N13: 0 | O13: 0 | P13: 0 | Q13: 0 | R13: 0 | S13: 0 | T13: 0 | W13: 扫荡开启 | X13: 2 | Y13: cheng | Z13: 0.7 | AA13: bg | AB13: -261 | AC13: -127 | AD13: 金牛座 | AE13: jinniuicon|jinniuname | AF13: Icon/function/ft008
A14: 140011 | B14: 140012 | C14: 金牛座2星 | D14: 2 | E14: 2 | F14: 54 | G14: 0 | H14: 0 | I14: 0 | J14: 0 | K14: 0 | L14: 0 | M14: 0 | N14: 0 | O14: 0 | P14: 0 | Q14: 0 | R14: 0 | S14: 0 | T14: 0 | W14: 开启技能成长 | X14: 2 | Y14: zi | Z14: 0.7 | AA14: bg | AB14: -190 | AC14: -50 | AD14: 金牛座 | AE14: jinniuicon|jinniuname | AF14: Icon/skill/ST00002
A15: 140012 | B15: 140013 | C15: 金牛座3星 | D15: 2 | E15: 3 | F15: 63 | G15: 0 | H15: 0 | I15: 0 | J15: 0 | K15: 0 | L15: 0 | M15: 0 | N15: 0 | O15: 0 | P15: 0 | Q15: 0 | R15: 0 | S15: 0 | T15: 0 | W15: 开启弗兰肯斯坦闯关 | X15: 2 | Y15: zi | Z15: 0.7 | AA15: bg | AB15: -60 | AC15: 50 | AD15: 金牛座 | AE15: jinniuicon|jinniuname | AF15: Icon/Hero/hero05
A16: 140013 | B16: 140014 | C16: 金牛座4星 | D16: 2 | E16: 4 | F16: 72 | G16: 0 | H16: 0 | I16: 0 | J16: 0 | K16: 0 | L16: 0 | M16: 0 | N16: 0 | O16: 0 | P16: 0 | Q16: 0 | R16: 0 | S16: 0 | T16: 0 | U16: 10-20 | W16: 天赋：幸运护佑 | X16: 2 | Y16: lan | Z16: 0.7 | AA16: bg | AB16: 45 | AC16: 196 | AD16: 金牛座 | AE16: jinniuicon|jinniuname | AF16: Icon/skill/ST00008 | AH16: 107
A17: 140014 | B17: 140015 | C17: 金牛座5星 | D17: 2 | E17: 5 | F17: 75 | G17: 0 | H17: 0 | I17: 0 | J17: 0 | K17: 0 | L17: 0 | M17: 0 | N17: 0 | O17: 0 | P17: 0 | Q17: 0 | R17: 0 | S17: 0 | T17: 0 | W17: 开启英雄闯关第三章 | X17: 2 | Y17: cheng | Z17: 0.7 | AA17: bg | AB17: 140 | AC17: 154 | AD17: 金牛座 | AE17: jinniuicon|jinniuname | AF17: Icon/function/ft005
A18: 140015 | B18: 140016 | C18: 金牛座6星 | D18: 2 | E18: 6 | F18: 81 | G18: 0 | H18: 0 | I18: 0 | J18: 0 | K18: 0 | L18: 0 | M18: 0 | N18: 0 | O18: 0 | P18: 0 | Q18: 0 | R18: 0 | S18: 0 | T18: 0 | V18: 100009-1 | W18: 守护神开启 | X18: 2 | Y18: jin | Z18: 0.7 | AA18: bg | AB18: 231 | AC18: 66 | AD18: 金牛座 | AE18: jinniuicon|jinniuname | AF18: Main/btnGod1
A19: 140016 | B19: 140017 | C19: 金牛座7星 | D19: 2 | E19: 7 | F19: 84 | G19: 0 | H19: 0 | I19: 0 | J19: 0 | K19: 0 | L19: 0 | M19: 0 | N19: 0 | O19: 0 | P19: 0 | Q19: 0 | R19: 0 | S19: 0 | T19: 0 | W19: 青铜秘境开启 | X19: 2 | Y19: lan | Z19: 0.7 | AA19: bg | AB19: 205 | AC19: 25 | AD19: 金牛座 | AE19: jinniuicon|jinniuname | AF19: Icon/function/ft006
A20: 140017 | B20: 140018 | C20: 金牛座8星 | D20: 2 | E20: 8 | F20: 87 | G20: 0 | H20: 0 | I20: 0 | J20: 0 | K20: 0 | L20: 0 | M20: 0 | N20: 0 | O20: 0 | P20: 0 | Q20: 0 | R20: 0 | S20: 0 | T20: 0 | U20: 10-20 | W20: 获得天赋点 | X20: 2 | Y20: cheng | Z20: 0.7 | AA20: bg | AB20: 140 | AC20: 10 | AD20: 金牛座 | AE20: shuangziicon|shuzngziname | AF20: Icon/function/ft007
A21: 140018 | B21: 140019 | C21: 金牛座9星 | D21: 2 | E21: 9 | F21: 96 | G21: 0 | H21: 0 | I21: 0 | J21: 0 | K21: 0 | L21: 0 | M21: 0 | N21: 0 | O21: 0 | P21: 0 | Q21: 0 | R21: 0 | S21: 0 | T21: 0 | U21: 10-20 | W21: 天赋：魔力护佑 | X21: 2 | Y21: zi | Z21: 0.7 | AA21: bg | AB21: 15 | AC21: -75 | AD21: 金牛座 | AE21: shuangziicon|shuzngziname | AF21: Icon/skill/ST00008 | AH21: 106
A22: 140019 | B22: 140020 | C22: 双子座1星 | D22: 3 | E22: 1 | F22: 99 | G22: 0 | H22: 0 | I22: 0 | J22: 0 | K22: 0 | L22: 0 | M22: 0 | N22: 0 | O22: 0 | P22: 0 | Q22: 0 | R22: 0 | S22: 0 | T22: 0 | W22: 芙蕾雅精英简单开启 | X22: 2 | Y22: cheng | Z22: 0.7 | AA22: bg | AB22: 113 | AC22: -78 | AD22: 双子座 | AE22: shuangziicon|shuzngziname | AF22: Icon/function/ft003
A23: 140020 | B23: 140021 | C23: 双子座2星 | D23: 3 | E23: 2 | F23: 102 | G23: 0 | H23: 0 | I23: 0 | J23: 0 | K23: 0 | L23: 0 | M23: 0 | N23: 0 | O23: 0 | P23: 0 | Q23: 0 | R23: 0 | S23: 0 | T23: 0 | W23: 开启英雄升品 | X23: 2 | Y23: zi | Z23: 0.7 | AA23: bg | AB23: 79 | AC23: 6 | AD23: 双子座 | AE23: shuangziicon|shuzngziname | AF23: Main/btnhero1
A24: 140021 | B24: 140022 | C24: 双子座3星 | D24: 3 | E24: 3 | F24: 105 | G24: 0 | H24: 0 | I24: 0 | J24: 0 | K24: 0 | L24: 0 | M24: 0 | N24: 0 | O24: 0 | P24: 0 | Q24: 0 | R24: 0 | S24: 0 | T24: 0 | U24: 10-20 | W24: 获得天赋点 | X24: 2 | Y24: zi | Z24: 0.7 | AA24: bg | AB24: 121 | AC24: 59 | AD24: 双子座 | AE24: shuangziicon|shuzngziname | AF24: Icon/function/ft007
A25: 140022 | B25: 140023 | C25: 双子座4星 | D25: 3 | E25: 4 | F25: 108 | G25: 0 | H25: 0 | I25: 0 | J25: 0 | K25: 0 | L25: 0 | M25: 0 | N25: 0 | O25: 0 | P25: 0 | Q25: 0 | R25: 0 | S25: 0 | T25: 0 | W25: 开启装备强化 | X25: 2 | Y25: lan | Z25: 0.7 | AA25: bg | AB25: 104 | AC25: 126 | AD25: 双子座 | AE25: shuangziicon|shuzngziname | AF25: Icon/function/ft016
A26: 140023 | B26: 140024 | C26: 双子座5星 | D26: 3 | E26: 5 | F26: 117 | G26: 0 | H26: 0 | I26: 0 | J26: 0 | K26: 0 | L26: 0 | M26: 0 | N26: 0 | O26: 0 | P26: 0 | Q26: 0 | R26: 0 | S26: 0 | T26: 0 | W26: 开启梅林闯关 | X26: 2 | Y26: cheng | Z26: 0.7 | AA26: bg | AB26: -11 | AC26: 119 | AD26: 双子座 | AE26: shuangziicon|shuzngziname | AF26: Icon/hero/hero03
A27: 140024 | B27: 140025 | C27: 双子座6星 | D27: 3 | E27: 6 | F27: 120 | G27: 0 | H27: 0 | I27: 0 | J27: 0 | K27: 0 | L27: 0 | M27: 0 | N27: 0 | O27: 0 | P27: 0 | Q27: 0 | R27: 0 | S27: 0 | T27: 0 | U27: 10-25 | W27: 获得天赋点 | X27: 2 | Y27: lan | Z27: 0.7 | AA27: bg | AB27: -14 | AC27: 182 | AD27: 双子座 | AE27: shuangziicon|shuzngziname | AF27: Main/btnskill1
A28: 140025 | B28: 0 | C28: 双子座7星 | D28: 3 | E28: 7 | F28: 10000 | G28: 0 | H28: 0 | I28: 0 | J28: 0 | K28: 0 | L28: 0 | M28: 0 | N28: 0 | O28: 0 | P28: 0 | Q28: 0 | R28: 0 | S28: 0 | T28: 0 | W28: 本次测试不开放 | X28: 2 | Y28: cheng | Z28: 0.7 | AA28: bg | AB28: -90 | AC28: 213 | AD28: 双子座 | AE28: shuangziicon|shuzngziname | AF28: Main/btnhero1

Sheet Sheet2
A1: int-id | B1: int-constellationid | C1: int-fatestarid | D1: int-starconsume | E1: int-HP | F1: int-attack | G1: int-defense | H1: int-superpower | I1: int-resist | J1: int-crit | K1: int-decrit | L1: int-curse | M1: int-decurse | N1: int-press | O1: int-depress | P1: int-restoreHP | Q1: int-MP | R1: int-restoreMP | S1: intArr:functionopen:| | T1: intArr:bonus1:|:- | U1: intArr:bonus2:|:- | V1: string-bubble | W1: int-bubbletype | X1: string-icon | Y1: float-iconsize | Z1: string-sceneid | AA1: float-coordinatex | AB1: float-coordinatey
A2: id | B2: 星座id | C2: 命星id | D2: 达到星数 | E2: HP | F2: 攻击力 | G2: 防御力 | H2: 霸气 | I2: 抗性 | J2: 暴击力 | K2: 抗暴力 | L2: 诅咒力 | M2: 抗咒力 | N2: 压制力 | O2: 抗压力 | P2: HP恢复能力 | Q2: MP | R2: MP恢复能力 | S2: 功能开放 | T2: 资源奖励 | U2: 物品奖励 | V2: 气泡文字描述 | W2: 气泡显示类型 | X2: 图标 | Y2: 图标大小系数 | Z2: 背景图 | AA2: x坐标 | AB2: y坐标
B3: 备注 1-白羊座 2-金牛座 3-双子 | D3: 所有英雄的英雄闯关 总星数之和 | W3: 1-常驻显示 2-点击弹出 | X3: 不同星座图标不同 | Y3: 图标的缩放系数 | Z3: 一个星座一个背景 配置在每个星座的第一颗命星的数据中
A4: =140001 -> 140001 | B4: 1 | C4: 1 | D4: 1 | E4: =IF(OR($C4=3,$C4=7),VLOOKUP($D4,Sheet3!$A:$E,5,),0) -> 0 | F4: =IF(OR($C4=1,$C4=5,$C4=9),VLOOKUP($D4,Sheet3!$A:$E,5,),0) -> 19 | G4: =IF(OR($C4=2,$C4=6,$C4=10),VLOOKUP($D4,Sheet3!$A:$E,5,),0) -> 0 | H4: =IF(OR($C4=4,$C4=8),VLOOKUP($D4,Sheet3!$A:$E,5,),0) -> 0 | I4: 0 | J4: 0 | K4: 0 | L4: 0 | M4: 0 | N4: 0 | O4: 0 | P4: 0 | Q4: 0 | R4: 0 | V4: =Sheet3!D2&"+"&Sheet3!E2 -> 攻击+19 | W4: 2 | X4: P0011 | Y4: 1 | Z4: map1 | AA4: -310 | AB4: 130
A5: 140002 | B5: 1 | C5: 2 | D5: 2 | E5: =IF(OR($C5=3,$C5=7),VLOOKUP($D5,Sheet3!$A:$E,5,),0) -> 0 | F5: =IF(OR($C5=1,$C5=5,$C5=9),VLOOKUP($D5,Sheet3!$A:$E,5,),0) -> 0 | G5: =IF(OR($C5=2,$C5=6,$C5=10),VLOOKUP($D5,Sheet3!$A:$E,5,),0) -> 19 | H5: =IF(OR($C5=4,$C5=8),VLOOKUP($D5,Sheet3!$A:$E,5,),0) -> 0 | I5: 0 | J5: 0 | K5: 0 | L5: 0 | M5: 0 | N5: 0 | O5: 0 | P5: 0 | Q5: 0 | R5: 0 | V5: =Sheet3!D3&"+"&Sheet3!E3 -> 防御+19 | W5: 2 | X5: P0011 | Y5: 1 | Z5: map1 | AA5: -137 | AB5: 130
A6: 140003 | B6: 1 | C6: 3 | D6: 3 | E6: =IF(OR($C6=3,$C6=7),VLOOKUP($D6,Sheet3!$A:$E,5,),0) -> 142 | F6: =IF(OR($C6=1,$C6=5,$C6=9),VLOOKUP($D6,Sheet3!$A:$E,5,),0) -> 0 | G6: =IF(OR($C6=2,$C6=6,$C6=10),VLOOKUP($D6,Sheet3!$A:$E,5,),0) -> 0 | H6: =IF(OR($C6=4,$C6=8),VLOOKUP($D6,Sheet3!$A:$E,5,),0) -> 0 | I6: 0 | J6: 0 | K6: 0 | L6: 0 | M6: 0 | N6: 0 | O6: 0 | P6: 0 | Q6: 0 | R6: 0 | V6: =Sheet3!D4&"+"&Sheet3!E4 -> 生命+142 | W6: 2 | X6: P0011 | Y6: 1 | Z6: map1 | AA6: -137 | AB6: -115
A7: 140004 | B7: 1 | C7: 4 | D7: 4 | E7: =IF(OR($C7=3,$C7=7),VLOOKUP($D7,Sheet3!$A:$E,5,),0) -> 0 | F7: =IF(OR($C7=1,$C7=5,$C7=9),VLOOKUP($D7,Sheet3!$A:$E,5,),0) -> 0 | G7: =IF(OR($C7=2,$C7=6,$C7=10),VLOOKUP($D7,Sheet3!$A:$E,5,),0) -> 0 | H7: =IF(OR($C7=4,$C7=8),VLOOKUP($D7,Sheet3!$A:$E,5,),0) -> 28 | I7: 0 | J7: 0 | K7: 0 | L7: 0 | M7: 0 | N7: 0 | O7: 0 | P7: 0 | Q7: 0 | R7: 0 | V7: =Sheet3!D5&"+"&Sheet3!E5 -> 霸气+28 | W7: 2 | X7: P0011 | Y7: 1 | Z7: map1 | AA7: 92 | AB7: -115
A8: 140005 | B8: 1 | C8: 5 | D8: 5 | E8: =IF(OR($C8=3,$C8=7),VLOOKUP($D8,Sheet3!$A:$E,5,),0) -> 0 | F8: =IF(OR($C8=1,$C8=5,$C8=9),VLOOKUP($D8,Sheet3!$A:$E,5,),0) -> 19 | G8: =IF(OR($C8=2,$C8=6,$C8=10),VLOOKUP($D8,Sheet3!$A:$E,5,),0) -> 0 | H8: =IF(OR($C8=4,$C8=8),VLOOKUP($D8,Sheet3!$A:$E,5,),0) -> 0 | I8: 0 | J8: 0 | K8: 0 | L8: 0 | M8: 0 | N8: 0 | O8: 0 | P8: 0 | Q8: 0 | R8: 0 | V8: =Sheet3!D6&"+"&Sheet3!E6 -> 攻击+19 | W8: 2 | X8: P0011 | Y8: 1 | Z8: map1 | AA8: 92 | AB8: 55
A9: 140006 | B9: 1 | C9: 6 | D9: 6 | E9: =IF(OR($C9=3,$C9=7),VLOOKUP($D9,Sheet3!$A:$E,5,),0) -> 0 | F9: =IF(OR($C9=1,$C9=5,$C9=9),VLOOKUP($D9,Sheet3!$A:$E,5,),0) -> 0 | G9: =IF(OR($C9=2,$C9=6,$C9=10),VLOOKUP($D9,Sheet3!$A:$E,5,),0) -> 19 | H9: =IF(OR($C9=4,$C9=8),VLOOKUP($D9,Sheet3!$A:$E,5,),0) -> 0 | I9: 0 | J9: 0 | K9: 0 | L9: 0 | M9: 0 | N9: 0 | O9: 0 | P9: 0 | Q9: 0 | R9: 0 | V9: =Sheet3!D7&"+"&Sheet3!E7 -> 防御+19 | W9: 2 | X9: P0011 | Y9: 1.3 | Z9: map1 | AA9: 340 | AB9: 55
A10: 140007 | B10: 1 | C10: 7 | D10: 7 | E10: =IF(OR($C10=3,$C10=7),VLOOKUP($D10,Sheet3!$A:$E,5,),0) -> 142 | F10: =IF(OR($C10=1,$C10=5,$C10=9),VLOOKUP($D10,Sheet3!$A:$E,5,),0) -> 0 | G10: =IF(OR($C10=2,$C10=6,$C10=10),VLOOKUP($D10,Sheet3!$A:$E,5,),0) -> 0 | H10: =IF(OR($C10=4,$C10=8),VLOOKUP($D10,Sheet3!$A:$E,5,),0) -> 0 | I10: 0 | J10: 0 | K10: 0 | L10: 0 | M10: 0 | N10: 0 | O10: 0 | P10: 0 | Q10: 0 | R10: 0 | V10: =Sheet3!D8&"+"&Sheet3!E8 -> 生命+142 | W10: 2 | X10: P0021 | Y10: 1 | Z10: map2 | AA10: -310 | AB10: 130
A11: 140008 | B11: 1 | C11: 8 | D11: 8 | E11: =IF(OR($C11=3,$C11=7),VLOOKUP($D11,Sheet3!$A:$E,5,),0) -> 0 | F11: =IF(OR($C11=1,$C11=5,$C11=9),VLOOKUP($D11,Sheet3!$A:$E,5,),0) -> 0 | G11: =IF(OR($C11=2,$C11=6,$C11=10),VLOOKUP($D11,Sheet3!$A:$E,5,),0) -> 0 | H11: =IF(OR($C11=4,$C11=8),VLOOKUP($D11,Sheet3!$A:$E,5,),0) -> 28 | I11: 0 | J11: 0 | K11: 0 | L11: 0 | M11: 0 | N11: 0 | O11: 0 | P11: 0 | Q11: 0 | R11: 0 | V11: =Sheet3!D9&"+"&Sheet3!E9 -> 霸气+28 | W11: 2 | X11: P0021 | Y11: 1 | Z11: map2 | AA11: -137 | AB11: 130
A12: 140009 | B12: 1 | C12: 9 | D12: 9 | E12: =IF(OR($C12=3,$C12=7),VLOOKUP($D12,Sheet3!$A:$E,5,),0) -> 0 | F12: =IF(OR($C12=1,$C12=5,$C12=9),VLOOKUP($D12,Sheet3!$A:$E,5,),0) -> 19 | G12: =IF(OR($C12=2,$C12=6,$C12=10),VLOOKUP($D12,Sheet3!$A:$E,5,),0) -> 0 | H12: =IF(OR($C12=4,$C12=8),VLOOKUP($D12,Sheet3!$A:$E,5,),0) -> 0 | I12: 0 | J12: 0 | K12: 0 | L12: 0 | M12: 0 | N12: 0 | O12: 0 | P12: 0 | Q12: 0 | R12: 0 | V12: =Sheet3!D10&"+"&Sheet3!E10 -> 攻击+19 | W12: 2 | X12: P0021 | Y12: 1 | Z12: map2 | AA12: -137 | AB12: -115
A13: 140010 | B13: 1 | C13: 10 | D13: 10 | E13: =IF(OR($C13=3,$C13=7),VLOOKUP($D13,Sheet3!$A:$E,5,),0) -> 0 | F13: =IF(OR($C13=1,$C13=5,$C13=9),VLOOKUP($D13,Sheet3!$A:$E,5,),0) -> 0 | G13: =IF(OR($C13=2,$C13=6,$C13=10),VLOOKUP($D13,Sheet3!$A:$E,5,),0) -> 19 | H13: =IF(OR($C13=4,$C13=8),VLOOKUP($D13,Sheet3!$A:$E,5,),0) -> 0 | I13: 0 | J13: 0 | K13: 0 | L13: 0 | M13: 0 | N13: 0 | O13: 0 | P13: 0 | Q13: 0 | R13: 0 | V13: =Sheet3!D11&"+"&Sheet3!E11 -> 防御+19 | W13: 1 | X13: P0021 | Y13: 1 | Z13: map2 | AA13: 92 | AB13: -115
A14: 140011 | B14: =B4+1 -> 2 | C14: =C4 -> 1 | D14: 11 | E14: =IF(OR($C14=3,$C14=7),VLOOKUP($D14,Sheet3!$A:$E,5,),0) -> 0 | F14: =IF(OR($C14=1,$C14=5,$C14=9),VLOOKUP($D14,Sheet3!$A:$E,5,),0) -> 19 | G14: =IF(OR($C14=2,$C14=6,$C14=10),VLOOKUP($D14,Sheet3!$A:$E,5,),0) -> 0 | H14: =IF(OR($C14=4,$C14=8),VLOOKUP($D14,Sheet3!$A:$E,5,),0) -> 0 | I14: 0 | J14: 0 | K14: 0 | L14: 0 | M14: 0 | N14: 0 | O14: 0 | P14: 0 | Q14: 0 | R14: 0 | V14: =Sheet3!D12&"+"&Sheet3!E12 -> 攻击+19 | W14: 2 | X14: P0021 | Y14: 1 | Z14: map2 | AA14: 92 | AB14: 55
A15: 140012 | B15: =B5+1 -> 2 | C15: =C5 -> 2 | D15: 12 | E15: =IF(OR($C15=3,$C15=7),VLOOKUP($D15,Sheet3!$A:$E,5,),0) -> 0 | F15: =IF(OR($C15=1,$C15=5,$C15=9),VLOOKUP($D15,Sheet3!$A:$E,5,),0) -> 0 | G15: =IF(OR($C15=2,$C15=6,$C15=10),VLOOKUP($D15,Sheet3!$A:$E,5,),0) -> 19 | H15: =IF(OR($C15=4,$C15=8),VLOOKUP($D15,Sheet3!$A:$E,5,),0) -> 0 | I15: 0 | J15: 0 | K15: 0 | L15: 0 | M15: 0 | N15: 0 | O15: 0 | P15: 0 | Q15: 0 | R15: 0 | V15: =Sheet3!D13&"+"&Sheet3!E13 -> 防御+19 | W15: 2 | X15: P0021 | Y15: 1.3 | Z15: map2 | AA15: 340 | AB15: 55
A16: 140013 | B16: =B6+1 -> 2 | C16: =C6 -> 3 | D16: 13 | E16: =IF(OR($C16=3,$C16=7),VLOOKUP($D16,Sheet3!$A:$E,5,),0) -> 142 | F16: =IF(OR($C16=1,$C16=5,$C16=9),VLOOKUP($D16,Sheet3!$A:$E,5,),0) -> 0 | G16: =IF(OR($C16=2,$C16=6,$C16=10),VLOOKUP($D16,Sheet3!$A:$E,5,),0) -> 0 | H16: =IF(OR($C16=4,$C16=8),VLOOKUP($D16,Sheet3!$A:$E,5,),0) -> 0 | I16: 0 | J16: 0 | K16: 0 | L16: 0 | M16: 0 | N16: 0 | O16: 0 | P16: 0 | Q16: 0 | R16: 0 | V16: =Sheet3!D14&"+"&Sheet3!E14 -> 生命+142 | W16: 2 | X16: P0031 | Y16: 1 | Z16: map3 | AA16: -310 | AB16: 130
A17: 140014 | B17: =B7+1 -> 2 | C17: =C7 -> 4 | D17: 14 | E17: =IF(OR($C17=3,$C17=7),VLOOKUP($D17,Sheet3!$A:$E,5,),0) -> 0 | F17: =IF(OR($C17=1,$C17=5,$C17=9),VLOOKUP($D17,Sheet3!$A:$E,5,),0) -> 0 | G17: =IF(OR($C17=2,$C17=6,$C17=10),VLOOKUP($D17,Sheet3!$A:$E,5,),0) -> 0 | H17: =IF(OR($C17=4,$C17=8),VLOOKUP($D17,Sheet3!$A:$E,5,),0) -> 28 | I17: 0 | J17: 0 | K17: 0 | L17: 0 | M17: 0 | N17: 0 | O17: 0 | P17: 0 | Q17: 0 | R17: 0 | V17: =Sheet3!D15&"+"&Sheet3!E15 -> 霸气+28 | W17: 2 | X17: P0031 | Y17: 1 | Z17: map3 | AA17: -137 | AB17: 130
A18: 140015 | B18: =B8+1 -> 2 | C18: =C8 -> 5 | D18: 15 | E18: =IF(OR($C18=3,$C18=7),VLOOKUP($D18,Sheet3!$A:$E,5,),0) -> 0 | F18: =IF(OR($C18=1,$C18=5,$C18=9),VLOOKUP($D18,Sheet3!$A:$E,5,),0) -> 19 | G18: =IF(OR($C18=2,$C18=6,$C18=10),VLOOKUP($D18,Sheet3!$A:$E,5,),0) -> 0 | H18: =IF(OR($C18=4,$C18=8),VLOOKUP($D18,Sheet3!$A:$E,5,),0) -> 0 | I18: 0 | J18: 0 | K18: 0 | L18: 0 | M18: 0 | N18: 0 | O18: 0 | P18: 0 | Q18: 0 | R18: 0 | V18: =Sheet3!D16&"+"&Sheet3!E16 -> 攻击+19 | W18: 2 | X18: P0031 | Y18: 1 | Z18: map3 | AA18: -137 | AB18: -115
A19: 140016 | B19: =B9+1 -> 2 | C19: =C9 -> 6 | D19: 16 | E19: =IF(OR($C19=3,$C19=7),VLOOKUP($D19,Sheet3!$A:$E,5,),0) -> 0 | F19: =IF(OR($C19=1,$C19=5,$C19=9),VLOOKUP($D19,Sheet3!$A:$E,5,),0) -> 0 | G19: =IF(OR($C19=2,$C19=6,$C19=10),VLOOKUP($D19,Sheet3!$A:$E,5,),0) -> 19 | H19: =IF(OR($C19=4,$C19=8),VLOOKUP($D19,Sheet3!$A:$E,5,),0) -> 0 | I19: 0 | J19: 0 | K19: 0 | L19: 0 | M19: 0 | N19: 0 | O19: 0 | P19: 0 | Q19: 0 | R19: 0 | V19: =Sheet3!D17&"+"&Sheet3!E17 -> 防御+19 | W19: 2 | X19: P0031 | Y19: 1 | Z19: map3 | AA19: 92 | AB19: -115
A20: 140017 | B20: =B10+1 -> 2 | C20: =C10 -> 7 | D20: 17 | E20: =IF(OR($C20=3,$C20=7),VLOOKUP($D20,Sheet3!$A:$E,5,),0) -> 142 | F20: =IF(OR($C20=1,$C20=5,$C20=9),VLOOKUP($D20,Sheet3!$A:$E,5,),0) -> 0 | G20: =IF(OR($C20=2,$C20=6,$C20=10),VLOOKUP($D20,Sheet3!$A:$E,5,),0) -> 0 | H20: =IF(OR($C20=4,$C20=8),VLOOKUP($D20,Sheet3!$A:$E,5,),0) -> 0 | I20: 0 | J20: 0 | K20: 0 | L20: 0 | M20: 0 | N20: 0 | O20: 0 | P20: 0 | Q20: 0 | R20: 0 | V20: =Sheet3!D18&"+"&Sheet3!E18 -> 生命+142 | W20: 2 | X20: P0031 | Y20: 1 | Z20: map3 | AA20: 92 | AB20: 55
A21: 140018 | B21: =B11+1 -> 2 | C21: =C11 -> 8 | D21: 18 | E21: =IF(OR($C21=3,$C21=7),VLOOKUP($D21,Sheet3!$A:$E,5,),0) -> 0 | F21: =IF(OR($C21=1,$C21=5,$C21=9),VLOOKUP($D21,Sheet3!$A:$E,5,),0) -> 0 | G21: =IF(OR($C21=2,$C21=6,$C21=10),VLOOKUP($D21,Sheet3!$A:$E,5,),0) -> 0 | H21: =IF(OR($C21=4,$C21=8),VLOOKUP($D21,Sheet3!$A:$E,5,),0) -> 28 | I21: 0 | J21: 0 | K21: 0 | L21: 0 | M21: 0 | N21: 0 | O21: 0 | P21: 0 | Q21: 0 | R21: 0 | V21: =Sheet3!D19&"+"&Sheet3!E19 -> 霸气+28 | W21: 2 | X21: P0031 | Y21: 1.3 | Z21: map3 | AA21: 340 | AB21: 55
A22: 140019 | B22: =B12+1 -> 2 | C22: =C12 -> 9 | D22: 19 | E22: =IF(OR($C22=3,$C22=7),VLOOKUP($D22,Sheet3!$A:$E,5,),0) -> 0 | F22: =IF(OR($C22=1,$C22=5,$C22=9),VLOOKUP($D22,Sheet3!$A:$E,5,),0) -> 19 | G22: =IF(OR($C22=2,$C22=6,$C22=10),VLOOKUP($D22,Sheet3!$A:$E,5,),0) -> 0 | H22: =IF(OR($C22=4,$C22=8),VLOOKUP($D22,Sheet3!$A:$E,5,),0) -> 0 | I22: 0 | J22: 0 | K22: 0 | L22: 0 | M22: 0 | N22: 0 | O22: 0 | P22: 0 | Q22: 0 | R22: 0 | V22: =Sheet3!D20&"+"&Sheet3!E20 -> 攻击+19 | W22: 2 | X22: P0031 | Y22: 1 | Z22: map3 | AA22: =AA4 -> -310 | AB22: =AB4 -> 130
A23: 140020 | B23: =B13+1 -> 2 | C23: =C13 -> 10 | D23: 20 | E23: =IF(OR($C23=3,$C23=7),VLOOKUP($D23,Sheet3!$A:$E,5,),0) -> 0 | F23: =IF(OR($C23=1,$C23=5,$C23=9),VLOOKUP($D23,Sheet3!$A:$E,5,),0) -> 0 | G23: =IF(OR($C23=2,$C23=6,$C23=10),VLOOKUP($D23,Sheet3!$A:$E,5,),0) -> 19 | H23: =IF(OR($C23=4,$C23=8),VLOOKUP($D23,Sheet3!$A:$E,5,),0) -> 0 | I23: 0 | J23: 0 | K23: 0 | L23: 0 | M23: 0 | N23: 0 | O23: 0 | P23: 0 | Q23: 0 | R23: 0 | V23: =Sheet3!D21&"+"&Sheet3!E21 -> 防御+19 | W23: 2 | X23: P0031 | Y23: 1 | Z23: map3 | AA23: =AA5 -> -137 | AB23: =AB5 -> 130
A24: 140021 | B24: =B14+1 -> 3 | C24: =C14 -> 1 | D24: 21 | E24: =IF(OR($C24=3,$C24=7),VLOOKUP($D24,Sheet3!$A:$E,5,),0) -> 0 | F24: =IF(OR($C24=1,$C24=5,$C24=9),VLOOKUP($D24,Sheet3!$A:$E,5,),0) -> 29 | G24: =IF(OR($C24=2,$C24=6,$C24=10),VLOOKUP($D24,Sheet3!$A:$E,5,),0) -> 0 | H24: =IF(OR($C24=4,$C24=8),VLOOKUP($D24,Sheet3!$A:$E,5,),0) -> 0 | I24: 0 | J24: 0 | K24: 0 | L24: 0 | M24: 0 | N24: 0 | O24: 0 | P24: 0 | Q24: 0 | R24: 0 | V24: =Sheet3!D22&"+"&Sheet3!E22 -> 攻击+29 | W24: 2 | X24: P0031 | Y24: 1 | Z24: map3 | AA24: =AA6 -> -137 | AB24: =AB6 -> -115
A25: 140022 | B25: =B15+1 -> 3 | C25: =C15 -> 2 | D25: 22 | E25: =IF(OR($C25=3,$C25=7),VLOOKUP($D25,Sheet3!$A:$E,5,),0) -> 0 | F25: =IF(OR($C25=1,$C25=5,$C25=9),VLOOKUP($D25,Sheet3!$A:$E,5,),0) -> 0 | G25: =IF(OR($C25=2,$C25=6,$C25=10),VLOOKUP($D25,Sheet3!$A:$E,5,),0) -> 29 | H25: =IF(OR($C25=4,$C25=8),VLOOKUP($D25,Sheet3!$A:$E,5,),0) -> 0 | I25: 0 | J25: 0 | K25: 0 | L25: 0 | M25: 0 | N25: 0 | O25: 0 | P25: 0 | Q25: 0 | R25: 0 | V25: =Sheet3!D23&"+"&Sheet3!E23 -> 防御+29 | W25: 2 | X25: P0031 | Y25: 1 | Z25: map3 | AA25: =AA7 -> 92 | AB25: =AB7 -> -115
A26: 140023 | B26: =B16+1 -> 3 | C26: =C16 -> 3 | D26: 23 | E26: =IF(OR($C26=3,$C26=7),VLOOKUP($D26,Sheet3!$A:$E,5,),0) -> 217 | F26: =IF(OR($C26=1,$C26=5,$C26=9),VLOOKUP($D26,Sheet3!$A:$E,5,),0) -> 0 | G26: =IF(OR($C26=2,$C26=6,$C26=10),VLOOKUP($D26,Sheet3!$A:$E,5,),0) -> 0 | H26: =IF(OR($C26=4,$C26=8),VLOOKUP($D26,Sheet3!$A:$E,5,),0) -> 0 | I26: 0 | J26: 0 | K26: 0 | L26: 0 | M26: 0 | N26: 0 | O26: 0 | P26: 0 | Q26: 0 | R26: 0 | V26: =Sheet3!D24&"+"&Sheet3!E24 -> 生命+217 | W26: 2 | X26: P0031 | Y26: 1 | Z26: map3 | AA26: =AA8 -> 92 | AB26: =AB8 -> 55
A27: 140024 | B27: =B17+1 -> 3 | C27: =C17 -> 4 | D27: 24 | E27: =IF(OR($C27=3,$C27=7),VLOOKUP($D27,Sheet3!$A:$E,5,),0) -> 0 | F27: =IF(OR($C27=1,$C27=5,$C27=9),VLOOKUP($D27,Sheet3!$A:$E,5,),0) -> 0 | G27: =IF(OR($C27=2,$C27=6,$C27=10),VLOOKUP($D27,Sheet3!$A:$E,5,),0) -> 0 | H27: =IF(OR($C27=4,$C27=8),VLOOKUP($D27,Sheet3!$A:$E,5,),0) -> 43 | I27: 0 | J27: 0 | K27: 0 | L27: 0 | M27: 0 | N27: 0 | O27: 0 | P27: 0 | Q27: 0 | R27: 0 | V27: =Sheet3!D25&"+"&Sheet3!E25 -> 霸气+43 | W27: 2 | X27: P0031 | Y27: 1 | Z27: map3 | AA27: =AA9 -> 340 | AB27: =AB9 -> 55
A28: 140025 | B28: =B18+1 -> 3 | C28: =C18 -> 5 | D28: 25 | E28: =IF(OR($C28=3,$C28=7),VLOOKUP($D28,Sheet3!$A:$E,5,),0) -> 0 | F28: =IF(OR($C28=1,$C28=5,$C28=9),VLOOKUP($D28,Sheet3!$A:$E,5,),0) -> 29 | G28: =IF(OR($C28=2,$C28=6,$C28=10),VLOOKUP($D28,Sheet3!$A:$E,5,),0) -> 0 | H28: =IF(OR($C28=4,$C28=8),VLOOKUP($D28,Sheet3!$A:$E,5,),0) -> 0 | I28: 0 | J28: 0 | K28: 0 | L28: 0 | M28: 0 | N28: 0 | O28: 0 | P28: 0 | Q28: 0 | R28: 0 | V28: =Sheet3!D26&"+"&Sheet3!E26 -> 攻击+29 | W28: 2 | X28: P0031 | Y28: 1 | Z28: map3 | AA28: =AA10 -> -310 | AB28: =AB10 -> 130
A29: 140026 | B29: =B19+1 -> 3 | C29: =C19 -> 6 | D29: 26 | E29: =IF(OR($C29=3,$C29=7),VLOOKUP($D29,Sheet3!$A:$E,5,),0) -> 0 | F29: =IF(OR($C29=1,$C29=5,$C29=9),VLOOKUP($D29,Sheet3!$A:$E,5,),0) -> 0 | G29: =IF(OR($C29=2,$C29=6,$C29=10),VLOOKUP($D29,Sheet3!$A:$E,5,),0) -> 29 | H29: =IF(OR($C29=4,$C29=8),VLOOKUP($D29,Sheet3!$A:$E,5,),0) -> 0 | I29: 0 | J29: 0 | K29: 0 | L29: 0 | M29: 0 | N29: 0 | O29: 0 | P29: 0 | Q29: 0 | R29: 0 | V29: =Sheet3!D27&"+"&Sheet3!E27 -> 防御+29 | W29: 2 | X29: P0031 | Y29: 1 | Z29: map3 | AA29: =AA11 -> -137 | AB29: =AB11 -> 130
A30: 140027 | B30: =B20+1 -> 3 | C30: =C20 -> 7 | D30: 27 | E30: =IF(OR($C30=3,$C30=7),VLOOKUP($D30,Sheet3!$A:$E,5,),0) -> 217 | F30: =IF(OR($C30=1,$C30=5,$C30=9),VLOOKUP($D30,Sheet3!$A:$E,5,),0) -> 0 | G30: =IF(OR($C30=2,$C30=6,$C30=10),VLOOKUP($D30,Sheet3!$A:$E,5,),0) -> 0 | H30: =IF(OR($C30=4,$C30=8),VLOOKUP($D30,Sheet3!$A:$E,5,),0) -> 0 | I30: 0 | J30: 0 | K30: 0 | L30: 0 | M30: 0 | N30: 0 | O30: 0 | P30: 0 | Q30: 0 | R30: 0 | V30: =Sheet3!D28&"+"&Sheet3!E28 -> 生命+217 | W30: 2 | X30: P0031 | Y30: 1 | Z30: map3 | AA30: =AA12 -> -137 | AB30: =AB12 -> -115
A31: 140028 | B31: =B21+1 -> 3 | C31: =C21 -> 8 | D31: 28 | E31: =IF(OR($C31=3,$C31=7),VLOOKUP($D31,Sheet3!$A:$E,5,),0) -> 0 | F31: =IF(OR($C31=1,$C31=5,$C31=9),VLOOKUP($D31,Sheet3!$A:$E,5,),0) -> 0 | G31: =IF(OR($C31=2,$C31=6,$C31=10),VLOOKUP($D31,Sheet3!$A:$E,5,),0) -> 0 | H31: =IF(OR($C31=4,$C31=8),VLOOKUP($D31,Sheet3!$A:$E,5,),0) -> 43 | I31: 0 | J31: 0 | K31: 0 | L31: 0 | M31: 0 | N31: 0 | O31: 0 | P31: 0 | Q31: 0 | R31: 0 | V31: =Sheet3!D29&"+"&Sheet3!E29 -> 霸气+43 | W31: 2 | X31: P0031 | Y31: 1 | Z31: map3 | AA31: =AA13 -> 92 | AB31: =AB13 -> -115
A32: 140029 | B32: =B22+1 -> 3 | C32: =C22 -> 9 | D32: 29 | E32: =IF(OR($C32=3,$C32=7),VLOOKUP($D32,Sheet3!$A:$E,5,),0) -> 0 | F32: =IF(OR($C32=1,$C32=5,$C32=9),VLOOKUP($D32,Sheet3!$A:$E,5,),0) -> 29 | G32: =IF(OR($C32=2,$C32=6,$C32=10),VLOOKUP($D32,Sheet3!$A:$E,5,),0) -> 0 | H32: =IF(OR($C32=4,$C32=8),VLOOKUP($D32,Sheet3!$A:$E,5,),0) -> 0 | I32: 0 | J32: 0 | K32: 0 | L32: 0 | M32: 0 | N32: 0 | O32: 0 | P32: 0 | Q32: 0 | R32: 0 | V32: =Sheet3!D30&"+"&Sheet3!E30 -> 攻击+29 | W32: 2 | X32: P0031 | Y32: 1 | Z32: map3 | AA32: =AA14 -> 92 | AB32: =AB14 -> 55
A33: 140030 | B33: =B23+1 -> 3 | C33: =C23 -> 10 | D33: 30 | E33: =IF(OR($C33=3,$C33=7),VLOOKUP($D33,Sheet3!$A:$E,5,),0) -> 0 | F33: =IF(OR($C33=1,$C33=5,$C33=9),VLOOKUP($D33,Sheet3!$A:$E,5,),0) -> 0 | G33: =IF(OR($C33=2,$C33=6,$C33=10),VLOOKUP($D33,Sheet3!$A:$E,5,),0) -> 29 | H33: =IF(OR($C33=4,$C33=8),VLOOKUP($D33,Sheet3!$A:$E,5,),0) -> 0 | I33: 0 | J33: 0 | K33: 0 | L33: 0 | M33: 0 | N33: 0 | O33: 0 | P33: 0 | Q33: 0 | R33: 0 | V33: =Sheet3!D31&"+"&Sheet3!E31 -> 防御+29 | W33: 2 | X33: P0031 | Y33: 1 | Z33: map3 | AA33: =AA15 -> 340 | AB33: =AB15 -> 55
... A123: 140120 | B123: =B113+1 -> 12 | C123: =C113 -> 10 | D123: 120 | E123: =IF(OR($C123=3,$C123=7),VLOOKUP($D123,Sheet3!$A:$E,5,),0) -> 0 | F123: =IF(OR($C123=1,$C123=5,$C123=9),VLOOKUP($D123,Sheet3!$A:$E,5,),0) -> 0 | G123: =IF(OR($C123=2,$C123=6,$C123=10),VLOOKUP($D123,Sheet3!$A:$E,5,),0) -> 283 | H123: =IF(OR($C123=4,$C123=8),VLOOKUP($D123,Sheet3!$A:$E,5,),0) -> 0 | I123: 0 | J123: 0 | K123: 0 | L123: 0 | M123: 0 | N123: 0 | O123: 0 | P123: 0 | Q123: 0 | R123: 0 | V123: =Sheet3!D121&"+"&Sheet3!E121 -> 防御+283 | W123: 2 | X123: P0031 | Y123: 1 | Z123: map3 | AA123: =AA105 -> 340 | AB123: =AB105 -> 55
D125: 1 | E125: =E4 -> 0 | F125: =F4 -> 19 | G125: =G4 -> 0 | H125: =H4 -> 0 | I125: =I4 -> 0 | J125: =J4 -> 0 | K125: =K4 -> 0 | L125: =L4 -> 0 | ... R125: =R4 -> 0
D126: 2 | E126: =E125+E5 -> 0 | F126: =F125+F5 -> 19 | G126: =G125+G5 -> 19 | H126: =H125+H5 -> 0 | I126: =I125+I5 -> 0 | J126: =J125+J5 -> 0 | K126: =K125+K5 -> 0 | L126: =L125+L5 -> 0 | ... R126: =R125+R5 -> 0
D127: 3 | E127: =E126+E6 -> 142 | F127: =F126+F6 -> 19 | G127: =G126+G6 -> 19 | H127: =H126+H6 -> 0 | I127: =I126+I6 -> 0 | J127: =J126+J6 -> 0 | K127: =K126+K6 -> 0 | L127: =L126+L6 -> 0 | ... R127: =R126+R6 -> 0
D128: 4 | E128: =E127+E7 -> 142 | F128: =F127+F7 -> 19 | G128: =G127+G7 -> 19 | H128: =H127+H7 -> 28 | I128: =I127+I7 -> 0 | J128: =J127+J7 -> 0 | K128: =K127+K7 -> 0 | L128: =L127+L7 -> 0 | ... R128: =R127+R7 -> 0
D129: 5 | E129: =E128+E8 -> 142 | F129: =F128+F8 -> 38 | G129: =G128+G8 -> 19 | H129: =H128+H8 -> 28 | I129: =I128+I8 -> 0 | J129: =J128+J8 -> 0 | K129: =K128+K8 -> 0 | L129: =L128+L8 -> 0 | ... R129: =R128+R8 -> 0
D130: 6 | E130: =E129+E9 -> 142 | F130: =F129+F9 -> 38 | G130: =G129+G9 -> 38 | H130: =H129+H9 -> 28 | I130: =I129+I9 -> 0 | J130: =J129+J9 -> 0 | K130: =K129+K9 -> 0 | L130: =L129+L9 -> 0 | ... R130: =R129+R9 -> 0
...

Sheet Sheet3
A1: 序号 | B1: 星座id | C1: 命星id | D1: 加成属性项 | E1: 属性值
A2: 1 | B2: 1 | C2: 1 | D2: 攻击 | E2: 19
A3: 2 | B3: 1 | C3: 2 | D3: 防御 | E3: 19
A4: 3 | B4: 1 | C4: 3 | D4: 生命 | E4: 142
A5: 4 | B5: 1 | C5: 4 | D5: 霸气 | E5: 28
A6: 5 | B6: 1 | C6: 5 | D6: 攻击 | E6: 19
A7: 6 | B7: 1 | C7: 6 | D7: 防御 | E7: 19
A8: 7 | B8: 1 | C8: 7 | D8: 生命 | E8: 142
A9: 8 | B9: 1 | C9: 8 | D9: 霸气 | E9: 28
A10: 9 | B10: 1 | C10: 9 | D10: 攻击 | E10: 19
A11: 10 | B11: 1 | C11: 10 | D11: 防御 | E11: 19
A12: 11 | B12: 2 | C12: 1 | D12: 攻击 | E12: 19
A13: 12 | B13: 2 | C13: 2 | D13: 防御 | E13: 19
... A121: 120 | B121: 12 | C121: 10 | D121: 防御 | E121: 283
