Workbook

Sheet Sheet1
A1: int-id | B1: int-storeId | C1: int-itemTplId | D1: int-buyType | E1: int-price | F1: int-times | G1: string-icon
B2: 商店ID | C2: 道具ID | D2: 消耗货币类型 | E2: 购买价格 | F2: 每次刷新可购买次数 | G2: 图标
D3: 1，铜币（游戏币） 2，金币（人民币） 3，竞技场货币 6，远征币 7，帮派币 11、恶魔币
A4: 1 | B4: 1 | C4: 400023 | D4: 2 | E4: 10 | F4: 1 | G4: chongzhi06
A5: 2 | B5: 1 | C5: 400001 | D5: 2 | E5: 25 | F5: 1 | G5: chongzhi06
A6: 3 | B6: 1 | C6: 400002 | D6: 2 | E6: 10 | F6: 1 | G6: chongzhi06
A7: 4 | B7: 1 | C7: 400017 | D7: 2 | E7: 50 | F7: 1
A8: 5 | B8: 1 | C8: 400013 | D8: 2 | E8: 50 | F8: 1
A9: 6 | B9: 1 | C9: 400015 | D9: 2 | E9: 150 | F9: 1
A10: 7 | B10: 1 | C10: 400012 | D10: 2 | E10: 100 | F10: 1
A11: 8 | B11: 1 | C11: 400007 | D11: 2 | E11: 20 | F11: 1
A12: 9 | B12: 1 | C12: 400031 | D12: 2 | E12: 100 | F12: 1
A13: 10 | B13: 2 | C13: 400021 | D13: 3 | E13: =VLOOKUP(C13,价格参考!A:C,3,)*VLOOKUP(D13,价格参考!$F$2:$G$12,2,)*VLOOKUP(B13,价格参考!$I$1:$J$13,2,) -> 200 | F13: 1
A14: 11 | B14: 2 | C14: 400022 | D14: 3 | E14: =VLOOKUP(C14,价格参考!A:C,3,)*VLOOKUP(D14,价格参考!$F$2:$G$12,2,)*VLOOKUP(B14,价格参考!$I$1:$J$13,2,) -> 500 | F14: 1
A15: 12 | B15: 2 | C15: 400023 | D15: 3 | E15: =VLOOKUP(C15,价格参考!A:C,3,)*VLOOKUP(D15,价格参考!$F$2:$G$12,2,)*VLOOKUP(B15,价格参考!$I$1:$J$13,2,) -> 1000 | F15: 1
A16: 13 | B16: 2 | C16: 400024 | D16: 3 | E16: =VLOOKUP(C16,价格参考!A:C,3,)*VLOOKUP(D16,价格参考!$F$2:$G$12,2,)*VLOOKUP(B16,价格参考!$I$1:$J$13,2,) -> 5000 | F16: 1
A17: 14 | B17: 2 | C17: 400017 | D17: 3 | E17: =VLOOKUP(C17,价格参考!A:C,3,)*VLOOKUP(D17,价格参考!$F$2:$G$12,2,)*VLOOKUP(B17,价格参考!$I$1:$J$13,2,) -> 100 | F17: 1
A18: 15 | B18: 2 | C18: 400012 | D18: 3 | E18: =VLOOKUP(C18,价格参考!A:C,3,)*VLOOKUP(D18,价格参考!$F$2:$G$12,2,)*VLOOKUP(B18,价格参考!$I$1:$J$13,2,) -> 50 | F18: 1
A19: 16 | B19: 2 | C19: 400003 | D19: 3 | E19: =VLOOKUP(C19,价格参考!A:C,3,)*VLOOKUP(D19,价格参考!$F$2:$G$12,2,)*VLOOKUP(B19,价格参考!$I$1:$J$13,2,) -> 500 | F19: 1
A20: 17 | B20: 2 | C20: 200001 | D20: 3 | E20: =VLOOKUP(C20,价格参考!A:C,3,)*VLOOKUP(D20,价格参考!$F$2:$G$12,2,)*VLOOKUP(B20,价格参考!$I$1:$J$13,2,) -> 1000 | F20: 1
A21: 18 | B21: 3 | C21: 400023 | D21: 2 | E21: 10 | F21: 1 | G21: chongzhi06
A22: 19 | B22: 3 | C22: 400001 | D22: 2 | E22: 25 | F22: 1 | G22: chongzhi06
A23: 20 | B23: 3 | C23: 400002 | D23: 2 | E23: 10 | F23: 1 | G23: chongzhi06
A24: 21 | B24: 3 | C24: 400017 | D24: 2 | E24: 50 | F24: 1
A25: 22 | B25: 3 | C25: 400014 | D25: 2 | E25: 100 | F25: 1
A26: 23 | B26: 3 | C26: 400016 | D26: 2 | E26: 200 | F26: 1
A27: 24 | B27: 3 | C27: 400007 | D27: 2 | E27: 20 | F27: 1
A28: 25 | B28: 3 | C28: 400012 | D28: 2 | E28: 100 | F28: 1
A29: 26 | B29: 3 | C29: 400031 | D29: 2 | E29: 100 | F29: 1
A30: 27 | B30: 4 | C30: 400021 | D30: 3 | E30: 200 | F30: 1
A31: 28 | B31: 4 | C31: 400022 | D31: 3 | E31: 100 | F31: 1
A32: 29 | B32: 4 | C32: 400023 | D32: 3 | E32: =VLOOKUP(C32,价格参考!A:C,3,)*VLOOKUP(D32,价格参考!$F$2:$G$12,2,)*VLOOKUP(B32,价格参考!$I$1:$J$13,2,) -> 1000 | F32: 1
A33: 30 | B33: 4 | C33: 400024 | D33: 3 | E33: =VLOOKUP(C33,价格参考!A:C,3,)*VLOOKUP(D33,价格参考!$F$2:$G$12,2,)*VLOOKUP(B33,价格参考!$I$1:$J$13,2,) -> 5000 | F33: 1
A34: 31 | B34: 4 | C34: 400017 | D34: 3 | E34: =VLOOKUP(C34,价格参考!A:C,3,)*VLOOKUP(D34,价格参考!$F$2:$G$12,2,)*VLOOKUP(B34,价格参考!$I$1:$J$13,2,) -> 100 | F34: 1
A35: 32 | B35: 4 | C35: 400012 | D35: 3 | E35: =VLOOKUP(C35,价格参考!A:C,3,)*VLOOKUP(D35,价格参考!$F$2:$G$12,2,)*VLOOKUP(B35,价格参考!$I$1:$J$13,2,) -> 50 | F35: 1
A36: 33 | B36: 4 | C36: 400003 | D36: 3 | E36: =VLOOKUP(C36,价格参考!A:C,3,)*VLOOKUP(D36,价格参考!$F$2:$G$12,2,)*VLOOKUP(B36,价格参考!$I$1:$J$13,2,) -> 500 | F36: 1
A37: 34 | B37: 4 | C37: 200001 | D37: 3 | E37: =VLOOKUP(C37,价格参考!A:C,3,)*VLOOKUP(D37,价格参考!$F$2:$G$12,2,)*VLOOKUP(B37,价格参考!$I$1:$J$13,2,) -> 1000 | F37: 1
A38: 35 | B38: 5 | C38: 400021 | D38: 6 | E38: =VLOOKUP(C38,价格参考!A:C,3,)*VLOOKUP(D38,价格参考!$F$2:$G$12,2,)*VLOOKUP(B38,价格参考!$I$1:$J$13,2,) -> 200 | F38: 1
A39: 36 | B39: 5 | C39: 400022 | D39: 6 | E39: =VLOOKUP(C39,价格参考!A:C,3,)*VLOOKUP(D39,价格参考!$F$2:$G$12,2,)*VLOOKUP(B39,价格参考!$I$1:$J$13,2,) -> 500 | F39: 1
A40: 37 | B40: 5 | C40: 400023 | D40: 6 | E40: =VLOOKUP(C40,价格参考!A:C,3,)*VLOOKUP(D40,价格参考!$F$2:$G$12,2,)*VLOOKUP(B40,价格参考!$I$1:$J$13,2,) -> 1000 | F40: 1
...

Sheet 价格参考
A1: id | C1: 对应基准元宝价格 | F1: 货币对应关系 | G1: 系数 | I1: 商店id | J1: 折扣
A2: 400021 | C2: 20 | F2: 1 | G2: 2000 | I2: 1 | J2: 1
A3: 400022 | C3: 50 | F3: 2 | G3: 1 | I3: 2 | J3: 1
A4: 400023 | C4: 100 | F4: 3 | G4: 10 | I4: 3 | J4: 1
A5: 400024 | C5: 500 | F5: 4 | I5: 4 | J5: 1
A6: 400001 | C6: 25 | F6: 5 | I6: 5 | J6: 1
A7: 400002 | C7: 25 | F7: 6 | G7: 10 | I7: 6 | J7: 1
A8: 400007 | C8: 20 | F8: 7 | G8: 10 | I8: 7 | J8: 1
A9: 400008 | C9: 50 | F9: 8 | I9: 8 | J9: 1
A10: 400009 | C10: 100 | F10: 9 | I10: 9 | J10: 1
A11: 400012 | C11: 5 | I11: 10 | J11: 1
A12: 400013 | C12: 2 | I12: 11 | J12: 1
A13: 400014 | C13: 4 | I13: 12 | J13: 1
A14: 400015 | C14: 8
A15: 400016 | C15: 20
A16: 400017 | C16: 10
A17: 400018 | C17: 50
A18: 400019 | C18: 10
A19: 400020 | C19: 200
A21: 500001 | C21: 12
A22: 500002 | C22: 12
A23: 500003 | C23: 12
A24: 500004 | C24: 12
A25: 500005 | C25: 12
A26: 500006 | C26: 12
... A291: 400025 | C291: 10

Sheet Sheet3
